#!/usr/bin/env python3
# -*- coding: utf-8 -*-
"""
タスク7: エラーハンドリングシステムの実際のエラーシミュレーションテスト

実際のエラー状況をシミュレートして、エラーハンドリングが正しく動作することを確認します。
"""

import sys
import os
import tempfile
import shutil
from pathlib import Path

# プロジェクトルートをパスに追加
project_root = Path(__file__).parent
sys.path.insert(0, str(project_root))

from PySide6.QtWidgets import QApplication
from PySide6.QtCore import QTimer
from src.gui.main_window import MainWindow
from src.utils.logging_config import setup_logging


class ErrorSimulationTester:
    """エラーシミュレーションテスター"""

    def __init__(self):
        self.app = QApplication.instance() or QApplication(sys.argv)
        self.main_window = None

    def setup_test_environment(self):
        """テスト環境をセットアップ"""
        # ログ設定
        setup_logging(level="DEBUG", enable_console=True)

        # メインウィンドウを作成
        self.main_window = MainWindow()
        print("メインウィンドウを作成しました")

    def test_file_access_error_simulation(self):
        """ファイルアクセスエラーのシミュレーション"""
        print("\n=== ファイルアクセスエラーのシミュレーション ===")

        # ファイルアクセスエラーをシミュレート
        error_message = "ファイルが見つかりません: /nonexistent/file.txt"
        thread_id = "test_thread_001"

        print(f"エラーメッセージ: {error_message}")
        print(f"スレッドID: {thread_id}")

        # エラータイプ分析のテスト
        error_type = self.main_window._analyze_error_type(error_message)
        print(f"分析されたエラータイプ: {error_type}")

        # _on_rebuild_errorメソッドを直接呼び出し（ダイアログは表示されない）
        try:
            # ダイアログを無効化するためのモック
            original_show_method = None
            if hasattr(self.main_window, '_handle_file_access_error'):
                # テスト用にダイアログ表示を無効化
                def mock_file_access_error(thread_id, error_message, thread_info):
                    print(f"  ファイルアクセスエラー処理が呼び出されました")
                    print(f"  スレッドID: {thread_id}")
                    print(f"  エラーメッセージ: {error_message}")

                original_method = self.main_window._handle_file_access_error
                self.main_window._handle_file_access_error = mock_file_access_error

                # エラーハンドリングを実行
                self.main_window._on_rebuild_error(thread_id, error_message)

                # 元のメソッドを復元
                self.main_window._handle_file_access_error = original_method

                print("✅ ファイルアクセスエラーのシミュレーションが成功しました")

        except Exception as e:
            print(f"❌ ファイルアクセスエラーのシミュレーションでエラー: {e}")

    def test_permission_error_simulation(self):
        """権限エラーのシミュレーション"""
        print("\n=== 権限エラーのシミュレーション ===")

        error_message = "アクセスが拒否されました: 権限がありません"
        thread_id = "test_thread_002"

        print(f"エラーメッセージ: {error_message}")
        print(f"スレッドID: {thread_id}")

        error_type = self.main_window._analyze_error_type(error_message)
        print(f"分析されたエラータイプ: {error_type}")

        try:
            # テスト用にダイアログ表示を無効化
            def mock_permission_error(thread_id, error_message, thread_info):
                print(f"  権限エラー処理が呼び出されました")
                print(f"  スレッドID: {thread_id}")
                print(f"  エラーメッセージ: {error_message}")
                print(f"  部分的インデックスのクリーンアップが実行されました")

            original_method = self.main_window._handle_permission_error
            self.main_window._handle_permission_error = mock_permission_error

            # エラーハンドリングを実行
            self.main_window._on_rebuild_error(thread_id, error_message)

            # 元のメソッドを復元
            self.main_window._handle_permission_error = original_method

            print("✅ 権限エラーのシミュレーションが成功しました")

        except Exception as e:
            print(f"❌ 権限エラーのシミュレーションでエラー: {e}")

    def test_resource_error_simulation(self):
        """リソースエラーのシミュレーション"""
        print("\n=== リソースエラーのシミュレーション ===")

        error_message = "メモリ不足: システムリソースが不足しています"
        thread_id = "test_thread_003"

        print(f"エラーメッセージ: {error_message}")
        print(f"スレッドID: {thread_id}")

        error_type = self.main_window._analyze_error_type(error_message)
        print(f"分析されたエラータイプ: {error_type}")

        try:
            # テスト用にダイアログ表示を無効化
            def mock_resource_error(thread_id, error_message, thread_info):
                print(f"  リソースエラー処理が呼び出されました")
                print(f"  スレッドID: {thread_id}")
                print(f"  エラーメッセージ: {error_message}")
                print(f"  部分的インデックスのクリーンアップが実行されました")

            original_method = self.main_window._handle_resource_error
            self.main_window._handle_resource_error = mock_resource_error

            # エラーハンドリングを実行
            self.main_window._on_rebuild_error(thread_id, error_message)

            # 元のメソッドを復元
            self.main_window._handle_resource_error = original_method

            print("✅ リソースエラーのシミュレーションが成功しました")

        except Exception as e:
            print(f"❌ リソースエラーのシミュレーションでエラー: {e}")

    def test_system_error_simulation(self):
        """システムエラーのシミュレーション"""
        print("\n=== システムエラーのシミュレーション ===")

        error_message = "予期しないシステムエラーが発生しました"
        thread_id = "test_thread_004"

        print(f"エラーメッセージ: {error_message}")
        print(f"スレッドID: {thread_id}")

        error_type = self.main_window._analyze_error_type(error_message)
        print(f"分析されたエラータイプ: {error_type}")

        try:
            # テスト用にダイアログ表示を無効化
            def mock_system_error(thread_id, error_message, thread_info):
                print(f"  システムエラー処理が呼び出されました")
                print(f"  スレッドID: {thread_id}")
                print(f"  エラーメッセージ: {error_message}")
                print(f"  部分的インデックスのクリーンアップが実行されました")

            original_method = self.main_window._handle_system_error
            self.main_window._handle_system_error = mock_system_error

            # エラーハンドリングを実行
            self.main_window._on_rebuild_error(thread_id, error_message)

            # 元のメソッドを復元
            self.main_window._handle_system_error = original_method

            print("✅ システムエラーのシミュレーションが成功しました")

        except Exception as e:
            print(f"❌ システムエラーのシミュレーションでエラー: {e}")

    def test_cleanup_functionality(self):
        """クリーンアップ機能のテスト"""
        print("\n=== クリーンアップ機能のテスト ===")

        try:
            # 部分的インデックスのクリーンアップをテスト
            print("部分的インデックスのクリーンアップをテスト中...")
            self.main_window._cleanup_partial_index()
            print("✅ 部分的インデックスのクリーンアップが成功しました")

            # エラークリーンアップをテスト
            print("エラークリーンアップをテスト中...")

            class MockThreadInfo:
                def __init__(self):
                    self.folder_path = "/test/folder"

            mock_thread_info = MockThreadInfo()
            self.main_window._perform_error_cleanup("test_thread", "test_error", mock_thread_info)
            print("✅ エラークリーンアップが成功しました")

        except Exception as e:
            print(f"❌ クリーンアップ機能のテストでエラー: {e}")

    def test_fallback_error_handling(self):
        """フォールバックエラーハンドリングのテスト"""
        print("\n=== フォールバックエラーハンドリングのテスト ===")

        try:
            # フォールバックエラーダイアログのテスト（ダイアログは表示されない）
            def mock_fallback_dialog(error_message):
                print(f"  フォールバックエラーダイアログが呼び出されました")
                print(f"  エラーメッセージ: {error_message}")

            original_method = self.main_window._show_fallback_error_dialog
            self.main_window._show_fallback_error_dialog = mock_fallback_dialog

            # フォールバックエラーハンドリングを実行
            self.main_window._show_fallback_error_dialog("テスト用フォールバックエラー")

            # 元のメソッドを復元
            self.main_window._show_fallback_error_dialog = original_method

            print("✅ フォールバックエラーハンドリングが成功しました")

        except Exception as e:
            print(f"❌ フォールバックエラーハンドリングのテストでエラー: {e}")

    def run_simulations(self):
        """すべてのシミュレーションを実行"""
        print("タスク7: エラーハンドリングシステムのエラーシミュレーションテスト開始")
        print("=" * 70)

        try:
            self.setup_test_environment()

            # 各シミュレーションを実行
            self.test_file_access_error_simulation()
            self.test_permission_error_simulation()
            self.test_resource_error_simulation()
            self.test_system_error_simulation()
            self.test_cleanup_functionality()
            self.test_fallback_error_handling()

            print("\n" + "=" * 70)
            print("✅ すべてのエラーシミュレーションが完了しました")

        except Exception as e:
            print(f"\n❌ シミュレーション実行中にエラーが発生しました: {e}")
            import traceback
            traceback.print_exc()

        finally:
            # メインウィンドウを閉じる
            if self.main_window:
                self.main_window.close()


def main():
    """メイン関数"""
    tester = ErrorSimulationTester()

    # シミュレーションを実行
    tester.run_simulations()

    print("\nシミュレーション完了。Enterキーを押して終了してください...")
    input()


if __name__ == "__main__":
    main()
